Workbook
Name eztoc197723_2: 'общо събрание'!$A$4
Name eztoc197723_3: 'общо събрание'!$A$7
Name eztoc197723_4: 'общо събрание'!$A$15
Name eztoc197723_5: 'общо събрание'!$A$23

Sheet main_database
A1: Name | B1: CV | C1: NACID | D1: SCOPUS | E1: Academic_title | F1: Advisor | G1: Joury_head | H1: Department | I1: PHD_from_FEBA | J1: Gender | K1: PHD_Awarded | L1: FIRST_PT_FEBA | M1: WORKED_OUTSIDE_OF_FEBA | N1: PHD_FROM_UNWE | O1: AI | P1: AI_corr | Q1: Time_from_phd_to_FEBA | R1: Q1_Scopus | S1: Scopus_all | T1: International_collaboration | U1: Only_national_collab | V1: Only_institutional_collaboration | W1: only_author | Z1: YES
A2: д-р Димитър Златинов | B2: https://www.uni-sofia.bg/index.php/bul/content/download/346778/2228517/version/1/file/CV+DZlatinov+BG+18.01.2026.pdf | C2: https://ras.nacid.bg/dissertation-preview/43740 | D2: https://www.scopus.com/authid/detail.uri?authorId=57200674599 | E2: Доц. | F2: Мариела Ненова-Амар | G2: Теодор Седларски | H2: Economics | I2: YES | J2: 1 | K2: 42348 | L2: 42188 | M2: YES | N2: NO | O2: =IF(I2="YES",1,0) -> 1 | P2: 1 | Q2: =K2-L2 -> 160 | R2: 0 | S2: 17 | T2: 0 | U2: 0.625 | V2: 0.188 | W2: =IF(S2>0,1-(T2+U2+V2),0) -> 0.187 | Z2: NO
A3: д-р Теодор Седларски | B3: https://www.uni-sofia.bg/index.php/bul/universitet_t/fakulteti/stopanski_fakultet/katedri_i_akademichen_s_stav/katedri/ikonomika/prepodavateli_katedra_ikonomika/prof_d_r_teodor_sedlarski | C3: https://ras.nacid.bg/dissertation-preview/37884 | D3: https://www.scopus.com/authid/detail.uri?authorId=57203805215&origin=resultslist | E3: Проф. | F3: Нансен Бахар | G3: No info | H3: Economics | I3: YES | J3: 1 | K3: 40294 | L3: 38701 | M3: YES | N3: NO | O3: =IF(I3="YES",1,0) -> 1 | P3: =IF(I3="YES",IF(L3-K3<365,1,0),0) -> 1 | Q3: =K3-L3 -> 1593 | R3: 0 | S3: 4 | T3: 1 | U3: 0 | V3: 0 | W3: =IF(S3>0,1-(T3+U3+V3),0) -> 0 | Z3: NO INFO
A4: д-р Ваня Иванова | B4: https://www.uni-sofia.bg/index.php/bul/content/download/276848/1810560/version/1/file/CV-V.Ivanova.pdf | C4: https://ras.nacid.bg/dissertation-preview/23280 | D4: https://www.scopus.com/authid/detail.uri?authorId=57832339600 | E4: Проф. | F4: проф. дикн Стоядин Савов | G4: проф. дикн Велко Mаринов | H4: Economics | I4: NO | J4: 0 | K4: 35576 | L4: 44845 | M4: YES | N4: NO | O4: =IF(I4="YES",1,0) -> 0 | P4: =IF(I4="YES",IF(L4-K4<365,1,0),0) -> 0 | Q4: =K4-L4 -> -9269 | R4: 0 | S4: 7 | T4: 0 | U4: 0.167 | V4: 0.667 | W4: =IF(S4>0,1-(T4+U4+V4),0) -> 0.166 | Z4: N/a
A5: д-р Милен Велушев | B5: https://www.uni-sofia.bg/index.php/bul/content/download/262963/1727823/version/1/file/CV-MB-bg+%281%29.pdf | C5: https://ras.nacid.bg/dissertation-preview/44000 | D5: https://www.scopus.com/authid/detail.uri?authorId=57614198900&origin=recordpage | E5: Доц. | F5: Стефан Петранов | G5: Доц. д-р Теодор Седларски | H5: Economics | I5: YES | J5: 1 | K5: 42429 | L5: 42257 | M5: NO | N5: NO | O5: =IF(I5="YES",1,0) -> 1 | P5: =IF(I5="YES",IF(L5-K5<365,1,0),0) -> 1 | Q5: =K5-L5 -> 172 | R5: 0 | S5: 1 | T5: 0 | U5: 1 | V5: 0 | W5: =IF(S5>0,1-(T5+U5+V5),0) -> 0
A6: д-р Соня Цветанова Георгиева | B6: https://www.uni-sofia.bg/index.php/bul/universitet_t/fakulteti/stopanski_fakultet/katedri_i_akademichen_s_stav/katedri/ikonomika/prepodavateli_katedra_ikonomika/doc_d_r_sonya_cvetanova_georgieva | C6: https://ras.nacid.bg/dissertation-preview/31155 | D6: https://www.scopus.com/authid/detail.uri?authorId=57222148408 | E6: Доц. | F6: Ненчо Димов | G6: Веселин Хаджиниколов | H6: Economics | I6: NO | J6: 0 | K6: 33428 | L6: 36145 | M6: YES | N6: NO | O6: =IF(I6="YES",1,0) -> 0 | P6: =IF(I6="YES",IF(L6-K6<365,1,0),0) -> 0 | Q6: =K6-L6 -> -2717 | R6: 0 | S6: 12 | T6: 0.083 | U6: 0.25 | V6: 0.417 | W6: =IF(S6>0,1-(T6+U6+V6),0) -> 0.25
A7: д-р Стела Ралева | B7: https://www.uni-sofia.bg/index.php/bul/content/download/253422/1669051/version/1/file/CV_Stela+Raleva__Bg.pdf | C7: https://ras.nacid.bg/dissertation-preview/27544 | D7: https://www.scopus.com/authid/detail.uri?authorId=56806829900&origin=resultslist | E7: Доц. | F7: Стати Василев Статев | G7: No info | H7: Economics | I7: NO | J7: 0 | K7: 38404 | L7: 44375 | M7: YES | N7: YES | O7: =IF(I7="YES",1,0) -> 0 | P7: =IF(I7="YES",IF(L7-K7<365,1,0),0) -> 0 | Q7: =K7-L7 -> -5971 | R7: 0 | S7: 5 | T7: 0 | U7: 0 | V7: 0.75 | W7: =IF(S7>0,1-(T7+U7+V7),0) -> 0.25
A8: д-р Цветан Мадански | B8: https://www.uni-sofia.bg/index.php/bul/content/download/294794/1919570/version/1/file/CV+-+%D0%A6%D0%B2%D0%B5%D1%82%D0%B0%D0%BD+%D0%9C%D0%B0%D0%B4%D0%B0%D0%BD%D1%81%D0%BA%D0%B8.pdf | C8: https://ras.nacid.bg/dissertation-preview/47652 | E8: Доц. | F8: Тодор Попов | G8: Желю Владимиров | H8: Economics | I8: YES | J8: 1 | K8: 43291 | L8: 43777 | M8: NO | N8: NO | O8: =IF(I8="YES",1,0) -> 1 | P8: =IF(I8="YES",IF(L8-K8<365,1,0),0) -> 0 | Q8: =K8-L8 -> -486 | R8: 0 | S8: 0 | T8: 0 | U8: 0 | V8: 0 | W8: =IF(S8>0,1-(T8+U8+V8),0) -> 0
A9: д-р Даниел Касабов | B9: https://www.uni-sofia.bg/index.php/bul/content/download/261454/1718561/version/1/file/CV+Daniel+Kasabov+-+BG.pdf | C9: https://ras.nacid.bg/dissertation-preview/49605 | D9: https://www.scopus.com/authid/detail.uri?authorId=59293941200&origin=resultslist | E9: Гл. ас. | F9: Петър Пандушев Чобанов | G9: Петър Пандушев Чобанов | H9: Economics | I9: NO | J9: 1 | K9: 43668 | L9: 44522 | M9: YES | N9: YES | O9: =IF(I9="YES",1,0) -> 0 | P9: =IF(I9="YES",IF(L9-K9<365,1,0),0) -> 0 | Q9: =365*3 -> 1095 | R9: 0 | S9: 1 | T9: 0 | U9: 0 | V9: 0 | W9: =IF(S9>0,1-(T9+U9+V9),0) -> 1
A10: д-р Илия Атанасов | B10: https://www.uni-sofia.bg/index.php/bul/content/download/249378/1644449/version/1/file/%D0%98%D0%BB%D0%B8%D1%8F+%D0%90%D1%82%D0%B0%D0%BD%D0%B0%D1%81%D0%BE%D0%B2+CV-BG.pdf | C10: https://ras.nacid.bg/dissertation-preview/61990 | D10: https://www.scopus.com/authid/detail.uri?authorId=57215082661 | E10: Гл. ас. | F10: Георги Димитров Менгов | G10: Димитър Златинов | H10: Economics | I10: YES | J10: 1 | K10: 44187 | L10: 43222 | M10: NO | N10: NO | O10: =IF(I10="YES",1,0) -> 1 | P10: =IF(I10="YES",IF(L10-K10<365,1,0),0) -> 1 | Q10: =K10-L10 -> 965 | R10: 0 | S10: 8 | T10: 0 | U10: 0.429 | V10: 0.429 | W10: =IF(S10>0,1-(T10+U10+V10),0) -> 0.142
A11: д-р Росица Златинска | B11: https://www.uni-sofia.bg/index.php/bul/content/download/296762/1931221/version/1/file/CV+BG+-+%D0%A0%D0%BE%D1%81%D0%B8%D1%86%D0%B0+%D0%97%D0%BB%D0%B0%D1%82%D0%B8%D0%BD%D1%81%D0%BA%D0%B0.pdf | C11: https://ras.nacid.bg/dissertation-preview/45870 | D11: https://www.scopus.com/authid/detail.uri?authorId=57416479900 | E11: Гл. ас. | F11: Пенчо Денчев Пенчев | G11: Пенчо Денчев Пенчев | H11: Economics | I11: NO | J11: 0 | K11: 42877 | L11: 45208 | M11: YES | N11: YES | O11: =IF(I11="YES",1,0) -> 0 | P11: =IF(I11="YES",IF(L11-K11<365,1,0),0) -> 0 | Q11: =K11-L11 -> -2331 | R11: 0 | S11: 6 | T11: 0 | U11: 0 | V11: 0.2 | W11: =IF(S11>0,1-(T11+U11+V11),0) -> 0.8
A12: д-р Любен Иванов | B12: https://www.uni-sofia.bg/index.php/bul/content/download/295181/1922122/version/1/file/Lyuben+Ivanov+CV+%28bg%29.pdf | C12: https://ras.nacid.bg/dissertation-preview/46596 | E12: Гл. ас. | F12: Георги Савов Чобанов | G12: Стефан Петранов | H12: Economics | I12: YES | J12: 1 | K12: 43039 | L12: 40339 | M12: YES | N12: NO | O12: =IF(I12="YES",1,0) -> 1 | P12: =IF(I12="YES",IF(L12-K12<365,1,0),0) -> 1 | Q12: =K12-L12 -> 2700 | R12: 0 | S12: 0 | T12: 0 | U12: 0 | V12: 0 | W12: =IF(S12>0,1-(T12+U12+V12),0) -> 0
A13: д-р Стоян Шаламанов | B13: https://www.uni-sofia.bg/index.php/bul/content/download/249404/1644567/version/1/file/3.CV_BG+5.pdf | C13: https://ras.nacid.bg/dissertation-preview/46590 | D13: https://www.scopus.com/authid/detail.uri?authorId=57996430300&origin=resultslist | E13: Гл. ас. | F13: Трайчо Стефанов Спасов | G13: Екатерина Стефанова Сотирова-Петкова | H13: Economics | I13: NO | J13: 1 | K13: 43017 | L13: 43780 | M13: YES | N13: YES | O13: =IF(I13="YES",1,0) -> 0 | P13: =IF(I13="YES",IF(L13-K13<365,1,0),0) -> 0 | Q13: =K13-L13 -> -763 | R13: 0 | S13: 4 | T13: 0 | U13: 0.333 | V13: 0.333 | W13: =IF(S13>0,1-(T13+U13+V13),0) -> 0.334
A14: д-р Радостина Ивчева-Георгиева | B14: https://www.uni-sofia.bg/index.php/bul/content/download/297402/1935034/version/1/file/CV+-+%D0%A0%D0%B0%D0%B4%D0%BE%D1%81%D1%82%D0%B8%D0%BD%D0%B0+%D0%98%D0%B2%D1%87%D0%B5%D0%B2%D0%B0.pdf | C14: https://ras.nacid.bg/dissertation-preview/70392 | D14: https://www.scopus.com/authid/detail.uri?authorId=57615520700&origin=resultslist | E14: Ас. | F14: Стефан Петранов | G14: Стела Ралева | H14: Economics | I14: YES | J14: 0 | K14: 45915 | L14: 45201 | M14: NO | N14: NO | O14: =IF(I14="YES",1,0) -> 1 | P14: =IF(I14="YES",IF(L14-K14<365,1,0),0) -> 1 | Q14: =K14-L14 -> 714 | R14: 0 | S14: 3 | T14: 0 | U14: 0.667 | V14: 0 | W14: =IF(S14>0,1-(T14+U14+V14),0) -> 0.333
A15: Диляна Славова | B15: No | C15: https://ras.nacid.bg/dissertation-preview/74744 | D15: No | E15: Ас. | F15: Димитър Златинов | G15: N/a | H15: Economics | I15: YES | J15: 0 | K15: =L15+365*5 -> 47763 | L15: 45938 | M15: NO INFO | N15: NO INFO | O15: =IF(I15="YES",1,0) -> 1 | P15: =IF(I15="YES",IF(L15-K15<365,1,0),0) -> 1 | Q15: =K15-L15 -> 1825 | R15: 0 | S15: 0 | T15: 0 | U15: 0 | V15: 0 | W15: =IF(S15>0,1-(T15+U15+V15),0) -> 0
A16: Илия Лингорски | B16: https://www.uni-sofia.bg/index.php/bul/content/download/297404/1935042/version/1/file/IL_CV_BG.pdf | C16: https://ras.nacid.bg/dissertation-preview/69769 | D16: No | E16: Ас. | F16: Стела Ралева | G16: N/a | H16: Economics | I16: YES | J16: 1 | K16: =L16+365*5 -> 47030 | L16: 45205 | M16: YES | N16: NO | O16: =IF(I16="YES",1,0) -> 1 | P16: =IF(I16="YES",IF(L16-K16<365,1,0),0) -> 1 | Q16: =K16-L16 -> 1825 | R16: 0 | S16: 0 | T16: 0 | U16: 0 | V16: 0 | W16: =IF(S16>0,1-(T16+U16+V16),0) -> 0
A17: Лидия Кабатлийска-Андонова | B17: https://www.uni-sofia.bg/index.php/bul/content/download/279136/1824366/version/1/file/CV_Lidiya+Kabatliyska_BG.pdf | C17: https://ras.nacid.bg/dissertation-preview/67487 | D17: No | E17: Ас. | F17: Стела Ралева | G17: N/a | H17: Economics | I17: YES | J17: 0 | K17: =L17+354*5 -> 46632 | L17: 44862 | M17: NO | N17: NO | O17: =IF(I17="YES",1,0) -> 1 | P17: =IF(I17="YES",IF(L17-K17<365,1,0),0) -> 1 | Q17: =K17-L17 -> 1770 | R17: 0 | S17: 0 | T17: 0 | U17: 0 | V17: 0 | W17: =IF(S17>0,1-(T17+U17+V17),0) -> 0
A18: д-р Олимпия Ведър-Величкова | B18: No | C18: https://ras.nacid.bg/dissertation-preview/43162 | D18: https://www.scopus.com/authid/detail.uri?authorId=60184186700&origin=resultslist | E18: Доц. | F18: Цветан Първанов Давидков | G18: Иванка Тодорова Мавродиева-Георгиева | H18: BA | I18: YES | J18: 0 | K18: 42185 | L18: 34710 | M18: NO | N18: NO | O18: =IF(I18="YES",1,0) -> 1 | P18: =IF(I18="YES",IF(L18-K18<365,1,0),0) -> 1 | Q18: =K18-L18 -> 7475 | R18: 0 | S18: 1 | T18: 0 | U18: 0 | V18: 0 | W18: =IF(S18>0,1-(T18+U18+V18),0) -> 1
A19: д.ик.н. Желю Владимиров | B19: https://www.uni-sofia.bg/index.php/bul/content/download/253686/1670765/version/1/file/0d_CV_%D0%96%D0%B5%D0%BB%D1%8E_%D0%92%D0%BB%D0%B0%D0%B4%D0%B8%D0%BC%D0%B8%D1%80%D0%BE%D0%B2_%D0%A1%D1%82%D0%A4.pdf | C19: https://ras.nacid.bg/dissertation-preview/13336 | D19: https://www.scopus.com/authid/detail.uri?authorId=36783781200&origin=resultslist | E19: Проф. | F19: Михаил Николаевич Руткевич | G19: Юрий Евгеньевич Волков | H19: BA | I19: NO | J19: 1 | K19: 31728 | L19: 36161 | M19: YES | N19: NO | O19: =IF(I19="YES",1,0) -> 0 | P19: =IF(I19="YES",IF(L19-K19<365,1,0),0) -> 0 | Q19: . | R19: 2 | S19: 17 | T19: 0.091 | U19: 0 | V19: 0.364 | W19: =IF(S19>0,1-(T19+U19+V19),0) -> 0.545
A20: д.ик.н. Невяна Кръстева | B20: https://www.uni-sofia.bg/index.php/bul/content/download/56798/466586/version/2/file/CV-NevyanaKrusteva2011.pdf | C20: https://ras.nacid.bg/dissertation-preview/13764 | D20: https://www.scopus.com/authid/detail.uri?authorId=59123107300&origin=resultslist | E20: Проф. | F20: Димитър Стоянов | G20: Гр. Желев | H20: BA | I20: NO | J20: 0 | K20: 32457 | L20: 36549 | M20: YES | N20: YES | O20: =IF(I20="YES",1,0) -> 0 | P20: =IF(I20="YES",IF(L20-K20<365,1,0),0) -> 0 | Q20: =K20-L20 -> -4092 | R20: 0 | S20: 5 | T20: 0 | U20: 0.5 | V20: 0 | W20: =IF(S20>0,1-(T20+U20+V20),0) -> 0.5
A21: д.ик.н. Десислава Йорданова | B21: https://www.uni-sofia.bg/index.php/bul/content/download/233490/1553846/version/1/file/CV_DYordanova.pdf | C21: https://ras.nacid.bg/dissertation-preview/41048 | D21: https://www.scopus.com/authid/detail.uri?authorId=58631627900&origin=resultslist | E21: Проф. | F21: Мария-Антония Таразон Родон | G21: Хуан Хосе Хименес | H21: BA | I21: NO | J21: 0 | K21: 41470 | L21: 39253 | M21: NO | N21: NO | O21: =IF(I21="YES",1,0) -> 0 | P21: =IF(I21="YES",IF(L21-K21<365,1,0),0) -> 0 | Q21: =K21-L21 -> 2217 | R21: 5 | S21: 23 | T21: 0.5 | U21: 0 | V21: 0.312 | W21: =IF(S21>0,1-(T21+U21+V21),0) -> 0.188
A22: д-р Владя Борисова | B22: No | C22: https://ras.nacid.bg/dissertation-preview/30186 | D22: https://www.scopus.com/authid/detail.uri?authorId=57202109484&origin=resultslist | E22: Проф. | F22: Божана Неделчева | G22: Пано Лулански | H22: BA | I22: NO | J22: 0 | K22: 38933 | L22: 44713 | M22: YES | N22: NO INFO | O22: =IF(I22="YES",1,0) -> 0 | P22: =IF(I22="YES",IF(L22-K22<365,1,0),0) -> 0 | Q22: =K22-L22 -> -5780 | R22: 1 | S22: 4 | T22: 0 | U22: 0 | V22: 0 | W22: =IF(S22>0,1-(T22+U22+V22),0) -> 1
A23: д-р Мирослава Христова | B23: No | C23: https://ras.nacid.bg/dissertation-preview/30905 | D23: https://www.scopus.com/authid/detail.uri?authorId=57203705327&origin=resultslist | E23: Доц. | F23: Жан-Пиер Ньово | G23: Жером Каби | H23: BA | I23: NO | J23: 0 | K23: 39546 | L23: 38643 | M23: NO | N23: NO | O23: =IF(I23="YES",1,0) -> 0 | P23: =IF(I23="YES",IF(L23-K23<365,1,0),0) -> 0 | Q23: =K23-L23 -> 903 | R23: 0 | S23: 1 | T23: 0 | U23: 0 | V23: 0 | W23: =IF(S23>0,1-(T23+U23+V23),0) -> 1
A24: д-р Тодор Ялъмов | B24: https://csd.eu/bg/experts/expert/Todor-Yalamov/ | C24: https://ras.nacid.bg/dissertation-preview/43001 | D24: https://www.scopus.com/authid/detail.uri?authorId=57364084200&origin=resultslist | E24: Доц. | F24: Анастасия Миланова Бънкова | G24: Цветан Първанов Давидков | H24: BA | I24: YES | J24: 1 | K24: 42165 | L24: 42746 | M24: NO INFO | N24: NO | O24: =IF(I24="YES",1,0) -> 1 | P24: =IF(I24="YES",IF(L24-K24<365,1,0),0) -> 0 | Q24: =K24-L24 -> -581 | R24: 0 | S24: 8 | T24: 0 | U24: 0 | V24: 0.6 | W24: =IF(S24>0,1-(T24+U24+V24),0) -> 0.4
A25: д-р Ия Петкова | B25: No | C25: https://ras.nacid.bg/dissertation-preview/40606 | E25: Доц. | F25: Цветан Първанов Давидков | G25: Желю Дечев Владимиров | H25: BA | I25: YES | J25: 0 | K25: 41533 | L25: 40422 | M25: NO | N25: NO | O25: =IF(I25="YES",1,0) -> 1 | P25: 1 | Q25: 1110 | R25: 0 | S25: 0 | T25: 0 | U25: 0 | V25: 0 | W25: =IF(S25>0,1-(T25+U25+V25),0) -> 0
A26: д-р Иван Ангелов | B26: No | C26: https://ras.nacid.bg/dissertation-preview/47632 | E26: Доц. | F26: Анастасия Миланова Бънкова | G26: Цветан Първанов Давидков | H26: BA | I26: YES | J26: 1 | K26: 43286 | L26: 43530 | M26: NO | N26: NO | O26: =IF(I26="YES",1,0) -> 1 | P26: =IF(I26="YES",IF(L26-K26<365,1,0),0) -> 1 | Q26: =K26-L26 -> -244 | R26: 0 | S26: 0 | T26: 0 | U26: 0 | V26: 0 | W26: =IF(S26>0,1-(T26+U26+V26),0) -> 0
A27: д-р Иванка Михайлова | B27: No | C27: https://ras.nacid.bg/dissertation-preview/47599 | D27: https://www.scopus.com/authid/detail.uri?authorId=59905827700&origin=resultslist | E27: Доц. | F27: Цветан Първанов Давидков | G27: Желю Дечев Владимиров | H27: BA | I27: YES | J27: 0 | K27: 43286 | L27: 40199 | M27: NO | N27: NO | O27: =IF(I27="YES",1,0) -> 1 | P27: =IF(I27="YES",IF(L27-K27<365,1,0),0) -> 1 | Q27: =K27-L27 -> 3087 | R27: 0 | S27: 1 | T27: 0 | U27: 0 | V27: 0 | W27: =IF(S27>0,1-(T27+U27+V27),0) -> 1
A28: д-р Рая Каназирева | B28: No | C28: https://ras.nacid.bg/dissertation-preview/42798 | D28: https://www.scopus.com/authid/detail.uri?authorId=59212397600&origin=resultslist | E28: Доц. | F28: Цветан Първанов Давидков | G28: Десислава Иванова Йорданова | H28: BA | I28: YES | J28: 0 | K28: 42124 | L28: 42655 | M28: NO | N28: NO | O28: =IF(I28="YES",1,0) -> 1 | P28: 0 | Q28: -531 | R28: 0 | S28: 3 | T28: 0.333 | U28: 0 | V28: 0.333 | W28: =IF(S28>0,1-(T28+U28+V28),0) -> 0.334
A29: д-р Кирил Величков | B29: https://www.linkedin.com/in/kiril-velitchkov-phd-7950366/ | C29: https://ras.nacid.bg/dissertation-preview/58317 | E29: Гл. ас. | F29: Магдалена Иванова | G29: Пано Лулански | H29: BA | I29: NO | J29: 1 | K29: 38076 | L29: 45208 | M29: NO | N29: YES | O29: =IF(I29="YES",1,0) -> 0 | P29: =IF(I29="YES",IF(L29-K29<365,1,0),0) -> 0 | Q29: =K29-L29 -> -7132 | R29: 0 | S29: 0 | T29: 0 | U29: 0 | V29: 0 | W29: =IF(S29>0,1-(T29+U29+V29),0) -> 0
A30: д-р Ирена Младенова | B30: No | C30: https://ras.nacid.bg/dissertation-preview/58027 | D30: https://www.scopus.com/authid/detail.uri?authorId=57732422200&origin=resultslist | E30: Гл. ас. | F30: Олимпия Ведър-Величкова | G30: Десислава Иванова Йорданова | H30: BA | I30: YES | J30: 0 | K30: 40199 | L30: 44985 | M30: NO | N30: NO | O30: =IF(I30="YES",1,0) -> 1 | P30: =IF(I30="YES",IF(L30-K30<365,1,0),0) -> 0 | Q30: =K30-L30 -> -4786 | R30: 1 | S30: 9 | T30: 0 | U30: 0.286 | V30: 0.143 | W30: =IF(S30>0,1-(T30+U30+V30),0) -> 0.571
A31: д-р Алексей Потебня | B31: No | C31: https://ras.nacid.bg/dissertation-preview/59979 | D31: https://www.scopus.com/results/results.uri?sort=plf-f&src=s&st1=Potebnya&st2=Aleksey&nlo=1&nlr=20&nls=count-f&sid=001ec1053d2796eedf35ef7a41329b27&sot=anl&sdt=aut&sl=38&s=AU-ID%28%22Potebnya%2C+Aleksey%22+60145455900%29&txGid=69be0c7fa50991a6f3eb3087cd5d2395&sessionSearchId=001ec1053d2796eedf35ef7a41329b27&limit=10 | E31: Гл. ас. | F31: Невяна Кръстева | G31: Десислава Иванова Йорданова | H31: BA | I31: YES | J31: 1 | K31: 45184 | L31: 44498 | M31: NO | N31: NO | O31: =IF(I31="YES",1,0) -> 1 | P31: =IF(I31="YES",IF(L31-K31<365,1,0),0) -> 1 | Q31: =K31-L31 -> 686 | R31: 0 | S31: 2 | T31: 0 | U31: 0 | V31: 0 | W31: =IF(S31>0,1-(T31+U31+V31),0) -> 1
A32: д-р Златина Михайлова | B32: No | C32: https://ras.nacid.bg/dissertation-preview/65111 | E32: Ас. | F32: Желю Дечев Владимиров | G32: Ия Тодорова Петкова-Гурбалова | H32: BA | I32: YES | J32: 0 | K32: 44474 | L32: 45681 | M32: NO | N32: NO | O32: =IF(I32="YES",1,0) -> 1 | P32: =IF(I32="YES",IF(L32-K32<365,1,0),0) -> 0 | Q32: =K32-L32 -> -1207 | R32: 0 | S32: 0 | T32: 0 | U32: 0 | V32: 0 | W32: =IF(S32>0,1-(T32+U32+V32),0) -> 0
A33: д-р Николета Войнова | B33: https://www.uni-sofia.bg/index.php/bul/content/download/336781/2169050/version/1/file/1.2.+%D0%9D%D0%B8%D0%BA%D0%BE%D0%BB%D0%B5%D1%82%D0%B0+%D0%92%D0%BE%D0%B9%D0%BD%D0%BE%D0%B2%D0%B0-CV-BG-2025.doc | C33: https://ras.nacid.bg/dissertation-preview/73965 | E33: Ас. | F33: Георги Н. Георгиев | G33: Слави М. Славов | H33: BA | I33: NO | J33: 0 | K33: 46028 | L33: 45895 | M33: YES | N33: NO | O33: =IF(I33="YES",1,0) -> 0 | P33: =IF(I33="YES",IF(L33-K33<365,1,0),0) -> 0 | Q33: =K33-L33 -> 133 | R33: 0 | S33: 0 | T33: 0 | U33: 0 | V33: 0 | W33: =IF(S33>0,1-(T33+U33+V33),0) -> 0
A34: Жанет Найденова | B34: https://www.linkedin.com/in/janetnaidenova/ | C34: https://ras.nacid.bg/dissertation-preview/66490 | E34: Ас. | F34: Retired, never did a PHD | G34: Retired, never did a PHD | H34: BA | I34: YES | J34: 0 | K34: =L34+365*5 -> 47026 | L34: 45201 | M34: NO | N34: NO | O34: =IF(I34="YES",1,0) -> 1 | P34: =IF(I34="YES",IF(L34-K34<365,1,0),0) -> 1 | Q34: =K34-L34 -> 1825 | R34: 0 | S34: 0 | T34: 0 | U34: 0 | V34: 0 | W34: =IF(S34>0,1-(T34+U34+V34),0) -> 0
A35: Ния Колева-Иванова | B35: No | C35: https://ras.nacid.bg/dissertation-preview/75999 | E35: Ас. | F35: Is not doing a PHD | G35: Is not doing a PHD | H35: BA | I35: YES | J35: 0 | K35: =365*5+L35 -> 47405 | L35: 45580 | M35: NO | N35: NO | O35: =IF(I35="YES",1,0) -> 1 | P35: =IF(I35="YES",IF(L35-K35<365,1,0),0) -> 1 | Q35: =K35-L35 -> 1825 | R35: 0 | S35: 0 | T35: 0 | U35: 0 | V35: 0 | W35: =IF(S35>0,1-(T35+U35+V35),0) -> 0
A36: Теодор Даскалов | B36: https://www.uni-sofia.bg/index.php/bul/universitet_t/fakulteti/stopanski_fakultet/katedri_i_akademichen_s_stav/katedri/stopansko_upravlenie/prepodavateli_katedra_stopansko_upravlenie/as_teodor_daskalov | E36: Ас. | F36: Невяна Кръстева | G36: N/a | H36: BA | I36: YES | J36: 1 | K36: =L36+365*5 -> 47405 | L36: 45580 | M36: NO | N36: NO | O36: =IF(I36="YES",1,0) -> 1 | P36: =IF(I36="YES",IF(L36-K36<365,1,0),0) -> 1 | Q36: =K36-L36 -> 1825 | R36: 0 | S36: 0 | T36: 0 | U36: 0 | V36: 0 | W36: =IF(S36>0,1-(T36+U36+V36),0) -> 0
A37: д-р Божидар Недев | C37: https://ras.nacid.bg/dissertation-preview/49158 | D37: https://www.scopus.com/authid/detail.uri?authorId=57205149916&origin=resultslist | E37: Доц. | F37: Теодор Седларски | G37: Стефан Петранов | H37: FA | I37: YES | J37: 1 | K37: 43521 | L37: 42314 | M37: NO | N37: NO | O37: =IF(I37="YES",1,0) -> 1 | P37: =IF(I37="YES",IF(L37-K37<365,1,0),0) -> 1 | Q37: =K37-L37 -> 1207 | R37: 1 | S37: 7 | T37: 0.143 | U37: 0.143 | V37: 0.714 | W37: =IF(S37>0,1-(T37+U37+V37),0) -> 0
A38: д-р Виктор Йоцов | C38: https://ras.nacid.bg/dissertation-preview/28176 | D38: https://www.scopus.com/authid/detail.uri?authorId=57192208329&origin=resultslist | E38: Проф. | F38: Гарабед Минасян | G38: Васил Тодоров | H38: FA | I38: NO | J38: 1 | K38: 37277 | L38: 45210 | M38: YES | N38: NO | O38: =IF(I38="YES",1,0) -> 0 | P38: =IF(I38="YES",IF(L38-K38<365,1,0),0) -> 0 | Q38: =K38-L38 -> -7933 | R38: 0 | S38: 8 | T38: 0 | U38: 0.333 | V38: 0.333 | W38: =IF(S38>0,1-(T38+U38+V38),0) -> 0.334
A39: д-р Елеонора Станчева | C39: https://ras.nacid.bg/dissertation-preview/29943 | D39: https://www.scopus.com/authid/detail.uri?authorId=57222472604&origin=resultslist | E39: Проф. | F39: Катерина Караиванова | G39: Коста Пергелов | H39: FA | I39: YES | J39: 0 | K39: 39357 | L39: 42317 | M39: NO | N39: NO | O39: =IF(I39="YES",1,0) -> 1 | P39: =IF(I39="YES",IF(L39-K39<365,1,0),0) -> 0 | Q39: =K39-L39 -> -2960 | R39: 0 | S39: 7 | T39: 0 | U39: 0 | V39: 1 | W39: =IF(S39>0,1-(T39+U39+V39),0) -> 0
A40: д-р Надя Велинова - Соколова | C40: https://ras.nacid.bg/dissertation-preview/25819 | D40: https://www.scopus.com/results/results.uri?sort=plf-f&src=s&st1=Sokolova&st2=Nadya&nlo=1&nlr=20&nls=count-f&sid=97ce249b9c7b914a4acd930399e81b2c&sot=anl&sdt=aut&sl=45&s=AU-ID%28%22Velinova-Sokolova%2C+Nadya%22+58535771500%29&txGid=7653ab75b76795bf2947a8b540d62b41&sessionSearchId=97ce249b9c7b914a4acd930399e81b2c&limit=10 | E40: Проф. | F40: Иван Попчев | G40: Дочо Дочев | H40: FA | I40: NO | J40: 0 | K40: 39924 | L40: 40327 | M40: NO | N40: YES | O40: =IF(I40="YES",1,0) -> 0 | P40: =IF(I40="YES",IF(L40-K40<365,1,0),0) -> 0 | Q40: =K40-L40 -> -403 | R40: 0 | S40: 1 | T40: 0 | U40: 0 | V40: 0 | W40: =IF(S40>0,1-(T40+U40+V40),0) -> 1
...

Sheet graph
B1: Economics and finance | C1: Business administration | D1: Finance and accounting | E1: Economics and governance by sectors | F1: Econonmetrics and statistics | G1: Senior Administration | H1: General Assembly | I1: Academic Affairs Committee | J1: Evaluation Committee
A2: AI coefficient | B2: =AVERAGE(main_database!O2:O17) -> 0.625 | C2: =AVERAGE(main_database!O18:O36) -> 0.63157895 | D2: =AVERAGE(main_database!O37:O50) -> 0.5 | E2: =AVERAGE(main_database!O51:O68) -> 0.5 | F2: =AVERAGE(main_database!O69:O84) -> 0.5625 | G2: =AVERAGE('Висша администрация'!B2:B9) -> 0.875 | H2: =AVERAGE('общо събрание'!B2:B31) -> 0.52631579 | I2: =AVERAGE(' Учебната комисия'!B2:B13) -> 0.9 | J2: =AVERAGE('комисия по атестация'!A2:B12) -> 0.71428571
A3: Corrected AI coefficient | B3: =AVERAGE(main_database!P2:P17) -> 0.5625 | C3: =AVERAGE(main_database!P18:P36) -> 0.42105263 | D3: =AVERAGE(main_database!P37:P50) -> 0.42857143 | E3: =AVERAGE(main_database!P51:P68) -> 0.33333333 | F3: =AVERAGE(main_database!P69:P84) -> 0.375 | G3: 0.625 | H3: =AVERAGE('общо събрание'!C2:C31) -> 0.42105263 | I3: =AVERAGE(' Учебната комисия'!C2:C13) -> 0.7 | J3: 0.71428571

Sheet Висша администрация
B1: Indicator
A2: Доц. д-р Атанас Георгиев | B2: 1 | C2: 1
A3: доц д-р Димитър Златинов - Зам.-декан "Учебна дейност" | B3: 1 | C3: 1
A4: доц. д-р Марселен Йовоган - Зам.-декан "Международна дейност и университетско сътрудничество" | B4: 0 | C4: 0
A5: доц. д-р Тодор Ялъмов - Зам.-декан "Научно-изследователската дейност, иновации и проекти" | B5: 1 | C5: =main_database!P24 -> 0
A6: доц. д-р Николай Нетов- Зам.-декан "Дигитална трансформация" | B6: 1 | C6: 1 | D6: https://ras.nacid.bg/dissertation-preview/43161
A7: доц. д-р Иван Ангелов - Зам.-декан "MBA програми и бизнес обучения" | B7: 1 | C7: 1
A8: доц. д-р Марина Стефанова - Зам.-декан "Устойчиво развитие, подкрепа и ангажираност" | B8: 1 | C8: 0
A9: гл.ас. д-р Илия Атанасов - Помощник-декан "Акредитация и рейтинг" | B9: 1 | C9: 1
B10: =AVERAGE(B2:B9) -> 0.875 | C10: =AVERAGE(C2:C9) -> 0.625

Sheet общо събрание
A1: Председател на ОС:
A2: проф. д-р Надя Велинова-Соколова | B2: 0 | C2: 0
A4: Зам.-председател на ОС:
A5: проф. д.н. Десислава Йорданова | B5: 0 | C5: 0
A7: Мандатна комисия
A8: Председател: доц. д-р Марселен Йовоган | B8: 0 | C8: 0
A9: Зам. председател: гл. ас. д-р Глория Христова | B9: 1 | C9: 1
A10: Членове:
A11: 1. доц. д-р Рая Каназирева | B11: 1 | C11: =main_database!P28 -> 0
A12: 2. гл. ас. д-р Илия Атанасов | B12: 1 | C12: 1
A13: 3. гл. ас. д-р Любен Иванов | B13: 1 | C13: 1
A15: Комисия по предложенията за органи на управление на факултета
A16: Председател: проф. д-р Ваня Иванова | B16: 0 | C16: 0
A17: Зам. председател: доц. д-р Божидар Недев | B17: 1 | C17: 1
A18: Членове:
A19: 1. доц. д-р Димитър Златинов | B19: 1 | C19: 1
A20: 2. доц. д-р Андрей Василев | B20: 0 | C20: 0
A21: 3. гл. ас. д-р Алексей Потебня | B21: 1 | C21: 1
A23: Комисия по произвеждане на избори:
A24: Председател: доц. д-р Илияна Анкова | B24: 1 | C24: 1
A25: Зам.-председател: доц. д-р Стела Ралева | B25: 0 | C25: 0
A26: Членове:
A27: 1. доц. д-р Цветан Мадански | B27: 1 | C27: 0
A28: 2. гл. ас. д-р Николай Кацарски | B28: 0 | C28: 0
A29: 3. гл. ас. д-р Емил Митов | B29: 0 | C29: 0
A30: 4. гл. ас. д-р Ирена Младенова | B30: 0 | C30: 0
A31: 5. гл. ас. д-р Бойко Амаров | B31: 1 | C31: 1

Sheet  Учебната комисия
A1: Председател:
A2: доц. д-р Димитър Златинов, Заместник-декан по учебната дейност и ръководител на катедра „Икономика“ | B2: 1 | C2: 1
A4: Членове:
A5: доц. д-р Атанас Георгиев, Декан на Стопанския факултет | B5: 1 | C5: 1
A6: доц. д-р Божидар Недев, ръководител на катедра "Финанси и счетоводство" | B6: 1 | C6: 1
A7: доц. д-р Марина Стефанова, ръководител на катедра "Икономика и управление по отрасли" | B7: 1 | C7: 0
A8: доц. д-р Николай Нетов, ръководител на катедра "Статистика и иконометрия" | B8: 1 | C8: 1
A9: доц. д-р Олимпия Ведър, ръководител на катедра „Стопанско управление“ | B9: 1 | C9: 1
A10: проф. д-р Елеонора Станчева-Тодорова, катедра "Финанси и счетоводство" | B10: 1 | C10: 0
A11: доц. д-р Боряна Пелова, катедра "Статистика и иконометрия" | B11: 1 | C11: 1
A12: доц. д-р Иванка Михайлова, катедра „Стопанско управление“ | B12: 1 | C12: 1
A13: доц. д-р Соня Георгиева, катедра "Икономика" | B13: 0 | C13: 0
A15: Десислава Лещарова, Главен инспектор администрация на Стопанския факултет | B15: 0
A17: Организационен секретар: Мая Тодорова | B17: 0
A18: Всичко | B18: =AVERAGE(B1:B17) -> 0.75
A19: Без научни лица | B19: =AVERAGE(B2:B13) -> 0.9

Sheet комисия по атестация
A1: Председател
A2: проф. д.н. Антон Герунов | B2: 1
A4: Зам.-председател
A5: доц. д-р Стела Ралева | B5: 0
A7: Членове
A8: 1. доц. д-р Божидар Недев | B8: 1
A9: 2. доц. д-р Деян Радев | B9: 0
A10: 3. доц. д-р Ия Петкова | B10: 1
A11: 4. доц. д-р Иванка Михайлова | B11: 1
A12: 5. гл. ас. д-р Глория Христова | B12: 1
B13: =AVERAGE(B2:B12) -> 0.71428571

Sheet Администрация
A1: Главен инспектор Администрация
A2: Десислава Лещарова
A3: Секретар на Стопанския факултет
A4: Маргарита Тодорова
A5: Инспектор Информационни дейности (СУСИ и eLearn)
A6: Мая Тодорова
A7: Инспектор Стопански дейности
A8: Маргарита Драганова
A9: Инспектор Докторанти
A10: Илона Цицелкова
A11: Инспектор Докторанти
A12: Анелия Стефанова
... A36: Боян Петров
